Workbook
Name Family: Sheet1!$A$2

Sheet Sheet1
A1: Design Table for: Cylinder Stave
B2: Theta@Sketch1 | C2: t@Sketch1 | D2: R@Sketch1 | E2: ISW@Sketch1 | F2: D1@Cut To Length
A3: 06 | B3: =90-Cylinder!$F$2 -> 75 | C3: =Cylinder!$B$1 -> 0.75 | D3: =Cylinder!$B$10 -> 2.75 | E3: =Cylinder!$B$12 -> 1.4235047 | F3: =Cylinder!$B$8 -> 9.75
A4: 07 | B4: =90-Cylinder!$F$2 -> 75 | C4: =Cylinder!$B$1 -> 0.75 | D4: =Cylinder!$C$10 -> 3.25 | E4: =Cylinder!$C$12 -> 1.6823238 | F4: =Cylinder!$C$8 -> 11.25
A5: 08 | B5: =90-Cylinder!$F$2 -> 75 | C5: =Cylinder!$B$1 -> 0.75 | D5: =Cylinder!$D$10 -> 3.75 | E5: =Cylinder!$D$12 -> 1.9411428 | F5: =Cylinder!$D$8 -> 12.75
A6: 09 | B6: =90-Cylinder!$F$2 -> 75 | C6: =Cylinder!$B$1 -> 0.75 | D6: =Cylinder!$E$10 -> 4.25 | E6: =Cylinder!$E$12 -> 2.1999619 | F6: =Cylinder!$E$8 -> 14.25
A7: 10 | B7: =90-Cylinder!$F$2 -> 75 | C7: =Cylinder!$B$1 -> 0.75 | D7: =Cylinder!$F$10 -> 4.75 | E7: =Cylinder!$F$12 -> 2.4587809 | F7: =Cylinder!$F$8 -> 15.75
A8: 11 | B8: =90-Cylinder!$F$2 -> 75 | C8: =Cylinder!$B$1 -> 0.75 | D8: =Cylinder!$G$10 -> 5.25 | E8: =Cylinder!$G$12 -> 2.7176 | F8: =Cylinder!$G$8 -> 17.25
A9: 12 | B9: =90-Cylinder!$F$2 -> 75 | C9: =Cylinder!$B$1 -> 0.75 | D9: =Cylinder!$H$10 -> 5.75 | E9: =Cylinder!$H$12 -> 2.976419 | F9: =Cylinder!$H$8 -> 18.75
A10: 13 | B10: =90-Cylinder!$F$2 -> 75 | C10: =Cylinder!$B$1 -> 0.75 | D10: =Cylinder!$I$10 -> 6.25 | E10: =Cylinder!$I$12 -> 3.2352381 | F10: =Cylinder!$I$8 -> 20.25
A11: 14 | B11: =90-Cylinder!$F$2 -> 75 | C11: =Cylinder!$B$1 -> 0.75 | D11: =Cylinder!$J$10 -> 6.75 | E11: =Cylinder!$J$12 -> 3.4940571 | F11: =Cylinder!$J$8 -> 21.75
A12: 15 | B12: =90-Cylinder!$F$2 -> 75 | C12: =Cylinder!$B$1 -> 0.75 | D12: =Cylinder!$K$10 -> 7.25 | E12: =Cylinder!$K$12 -> 3.7528762 | F12: =Cylinder!$K$8 -> 23.25
A13: 16 | B13: =90-Cylinder!$F$2 -> 75 | C13: =Cylinder!$B$1 -> 0.75 | D13: =Cylinder!$L$10 -> 7.75 | E13: =Cylinder!$L$12 -> 4.0116952 | F13: =Cylinder!$L$8 -> 24.75
A14: 17 | B14: =90-Cylinder!$F$2 -> 75 | C14: =Cylinder!$B$1 -> 0.75 | D14: =Cylinder!$M$10 -> 8.25 | E14: =Cylinder!$M$12 -> 4.2705142 | F14: =Cylinder!$M$8 -> 26.25
A15: 18 | B15: =90-Cylinder!$F$2 -> 75 | C15: =Cylinder!$B$1 -> 0.75 | D15: =Cylinder!$N$10 -> 8.75 | E15: =Cylinder!$N$12 -> 4.5293333 | F15: =Cylinder!$N$8 -> 27.75
A16: 19 | B16: =90-Cylinder!$F$2 -> 75 | C16: =Cylinder!$B$1 -> 0.75 | D16: =Cylinder!$O$10 -> 9.25 | E16: =Cylinder!$O$12 -> 4.7881523 | F16: =Cylinder!$O$8 -> 29.25
A17: 20 | B17: =90-Cylinder!$F$2 -> 75 | C17: =Cylinder!$B$1 -> 0.75 | D17: =Cylinder!$P$10 -> 9.75 | E17: =Cylinder!$P$12 -> 5.0469714 | F17: =Cylinder!$P$8 -> 30.75
A18: 21 | B18: =90-Cylinder!$F$2 -> 75 | C18: =Cylinder!$B$1 -> 0.75 | D18: =Cylinder!$Q$10 -> 10.25 | E18: =Cylinder!$Q$12 -> 5.3057904 | F18: =Cylinder!$Q$8 -> 32.25
A19: 22 | B19: =90-Cylinder!$F$2 -> 75 | C19: =Cylinder!$B$1 -> 0.75 | D19: =Cylinder!$R$10 -> 10.75 | E19: =Cylinder!$R$12 -> 5.5646095 | F19: =Cylinder!$R$8 -> 33.75
A20: 23 | B20: =90-Cylinder!$F$2 -> 75 | C20: =Cylinder!$B$1 -> 0.75 | D20: =Cylinder!$S$10 -> 11.25 | E20: =Cylinder!$S$12 -> 5.8234285 | F20: =Cylinder!$S$8 -> 35.25
A21: 24 | B21: =90-Cylinder!$F$2 -> 75 | C21: =Cylinder!$B$1 -> 0.75 | D21: =Cylinder!$T$10 -> 11.75 | E21: =Cylinder!$T$12 -> 6.0822476 | F21: =Cylinder!$T$8 -> 36.75
A22: 25 | B22: =90-Cylinder!$F$2 -> 75 | C22: =Cylinder!$B$1 -> 0.75 | D22: =Cylinder!$U$10 -> 12.25 | E22: =Cylinder!$U$12 -> 6.3410666 | F22: =Cylinder!$U$8 -> 38.25
A23: 26 | B23: =90-Cylinder!$F$2 -> 75 | C23: =Cylinder!$B$1 -> 0.75 | D23: =Cylinder!$V$10 -> 12.75 | E23: =Cylinder!$V$12 -> 6.5998857 | F23: =Cylinder!$V$8 -> 39.75
A24: 27 | B24: =90-Cylinder!$F$2 -> 75 | C24: =Cylinder!$B$1 -> 0.75 | D24: =Cylinder!$W$10 -> 13.25 | E24: =Cylinder!$W$12 -> 6.8587047 | F24: =Cylinder!$W$8 -> 41.25
A25: 28 | B25: =90-Cylinder!$F$2 -> 75 | C25: =Cylinder!$B$1 -> 0.75 | D25: =Cylinder!$X$10 -> 13.75 | E25: =Cylinder!$X$12 -> 7.1175237 | F25: =Cylinder!$X$8 -> 42.75
A26: 29 | B26: =90-Cylinder!$F$2 -> 75 | C26: =Cylinder!$B$1 -> 0.75 | D26: =Cylinder!$Y$10 -> 14.25 | E26: =Cylinder!$Y$12 -> 7.3763428 | F26: =Cylinder!$Y$8 -> 44.25
A27: 30 | B27: =90-Cylinder!$F$2 -> 75 | C27: =Cylinder!$B$1 -> 0.75 | D27: =Cylinder!$Z$10 -> 14.75 | E27: =Cylinder!$Z$12 -> 7.6351618 | F27: =Cylinder!$Z$8 -> 45.75
A28: 31 | B28: =90-Cylinder!$F$2 -> 75 | C28: =Cylinder!$B$1 -> 0.75 | D28: =Cylinder!$AA$10 -> 15.25 | E28: =Cylinder!$AA$12 -> 7.8939809 | F28: =Cylinder!$AA$8 -> 47.25
A29: 32 | B29: =90-Cylinder!$F$2 -> 75 | C29: =Cylinder!$B$1 -> 0.75 | D29: =Cylinder!$AB$10 -> 15.75 | E29: =Cylinder!$AB$12 -> 8.1527999 | F29: =Cylinder!$AB$8 -> 48.75
A30: 33 | B30: =90-Cylinder!$F$2 -> 75 | C30: =Cylinder!$B$1 -> 0.75 | D30: =Cylinder!$AC$10 -> 16.25 | E30: =Cylinder!$AC$12 -> 8.411619 | F30: =Cylinder!$AC$8 -> 50.25
A31: 34 | B31: =90-Cylinder!$F$2 -> 75 | C31: =Cylinder!$B$1 -> 0.75 | D31: =Cylinder!$AD$10 -> 16.75 | E31: =Cylinder!$AD$12 -> 8.670438 | F31: =Cylinder!$AD$8 -> 51.75
A32: 35 | B32: =90-Cylinder!$F$2 -> 75 | C32: =Cylinder!$B$1 -> 0.75 | D32: =Cylinder!$AE$10 -> 17.25 | E32: =Cylinder!$AE$12 -> 8.9292571 | F32: =Cylinder!$AE$8 -> 53.25
A33: 36 | B33: =90-Cylinder!$F$2 -> 75 | C33: =Cylinder!$B$1 -> 0.75 | D33: =Cylinder!$AF$10 -> 17.75 | E33: =Cylinder!$AF$12 -> 9.1880761 | F33: =Cylinder!$AF$8 -> 54.75

Sheet Cylinder
A1: Board Thickness (in): | B1: 0.75 | C1: Saw Blade Kerf (in): | F1: 0.095 | G1: Horizontal Kerf (in): | J1: =F1/COS(J2) -> 0.095 | K1: =NOW() -> 41405.987
A2: Number of Staves: | B2: 12 | C2: Stave Bevel (180/n): | F2: =180/B2 -> 15
A3: Aspect Ratio (NL/OD): | B3: 1.5 | C3: Extra Stave Width (in): | F3: 0 | G3: Extra Length (in): | J3: 0.75
A4: Narrowest Turned Shell OD - ID (in): | B4: 0.5 | C4: Wood Type 1 ($/in^3): | F4: 0.05 | G4: Wood Type 2 ($/in^3) | J4: 0.05
A6: Dimensions | B6: 6 in | C6: 7 in | D6: 8 in | E6: 9 in | F6: 10 in | G6: 11 in | H6: 12 in | I6: 13 in | J6: 14 in | K6: 15 in | L6: 16 in | M6: 17 in | N6: 18 in | O6: 19 in | P6: 20 in | Q6: 21 in | R6: 22 in | S6: 23 in | T6: 24 in | U6: 25 in | V6: 26 in | W6: 27 in | X6: 28 in | Y6: 29 in | Z6: 30 in | AA6: 31 in | AB6: 32 in | AC6: 33 in | AD6: 34 in | AE6: 35 in | AF6: 36 in
A7: OD - Nominal Diameter (in) | B7: 6 | C7: 7 | D7: 8 | E7: 9 | F7: 10 | G7: 11 | H7: 12 | I7: 13 | J7: 14 | K7: 15 | L7: 16 | M7: 17 | N7: 18 | O7: 19 | P7: 20 | Q7: 21 | R7: 22 | S7: 23 | T7: 24 | U7: 25 | V7: 26 | W7: 27 | X7: 28 | Y7: 29 | Z7: 30 | AA7: 31 | AB7: 32 | AC7: 33 | AD7: 34 | AE7: 35 | AF7: 36
A8: L - Cut To Length (in) | B8: =CEILING(B9+$J$3, 0.25) -> 9.75 | C8: =CEILING(C9+$J$3, 0.25) -> 11.25 | D8: =CEILING(D9+$J$3, 0.25) -> 12.75 | E8: =CEILING(E9+$J$3, 0.25) -> 14.25 | F8: =CEILING(F9+$J$3, 0.25) -> 15.75 | G8: =CEILING(G9+$J$3, 0.25) -> 17.25 | H8: =CEILING(H9+$J$3, 0.25) -> 18.75 | I8: =CEILING(I9+$J$3, 0.25) -> 20.25 | ... AF8: =CEILING(AF9+$J$3, 0.25) -> 54.75
A9: NL - Nominal Length (in) | B9: =B7*$B$3 -> 9 | C9: =C7*$B$3 -> 10.5 | D9: =D7*$B$3 -> 12 | E9: =E7*$B$3 -> 13.5 | F9: =F7*$B$3 -> 15 | G9: =G7*$B$3 -> 16.5 | H9: =H7*$B$3 -> 18 | I9: =I7*$B$3 -> 19.5 | ... AF9: =AF7*$B$3 -> 54
A10: R - Circumradius (in) | B10: =(B7-$B$4)/2 -> 2.75 | C10: =(C7-$B$4)/2 -> 3.25 | D10: =(D7-$B$4)/2 -> 3.75 | E10: =(E7-$B$4)/2 -> 4.25 | F10: =(F7-$B$4)/2 -> 4.75 | G10: =(G7-$B$4)/2 -> 5.25 | H10: =(H7-$B$4)/2 -> 5.75 | I10: =(I7-$B$4)/2 -> 6.25 | ... AF10: =(AF7-$B$4)/2 -> 17.75
A11: r - Inradius (in) | B11: =B10*COS(PI()/$B$2) -> 2.656296 | C11: =C10*COS(PI()/$B$2) -> 3.1392589 | D11: =D10*COS(PI()/$B$2) -> 3.6222218 | E11: =E10*COS(PI()/$B$2) -> 4.1051848 | F11: =F10*COS(PI()/$B$2) -> 4.5881477 | G11: =G10*COS(PI()/$B$2) -> 5.0711106 | H11: =H10*COS(PI()/$B$2) -> 5.5540735 | I11: =I10*COS(PI()/$B$2) -> 6.0370364 | ... AF11: =AF10*COS(PI()/$B$2) -> 17.145183
A12: ISW - Inner Stave Width (in) | B12: =2*B10*SIN(PI()/$B$2) -> 1.4235047 | C12: =2*C10*SIN(PI()/$B$2) -> 1.6823238 | D12: =2*D10*SIN(PI()/$B$2) -> 1.9411428 | E12: =2*E10*SIN(PI()/$B$2) -> 2.1999619 | F12: =2*F10*SIN(PI()/$B$2) -> 2.4587809 | G12: =2*G10*SIN(PI()/$B$2) -> 2.7176 | H12: =2*H10*SIN(PI()/$B$2) -> 2.976419 | I12: =2*I10*SIN(PI()/$B$2) -> 3.2352381 | ... AF12: =2*AF10*SIN(PI()/$B$2) -> 9.1880761
A13: OSW - Outer Stave Width (in) | B13: =2*(B11+$B$1)*TAN(PI()/$B$2) -> 1.8254285 | C13: =2*(C11+$B$1)*TAN(PI()/$B$2) -> 2.0842476 | D13: =2*(D11+$B$1)*TAN(PI()/$B$2) -> 2.3430666 | E13: =2*(E11+$B$1)*TAN(PI()/$B$2) -> 2.6018857 | F13: =2*(F11+$B$1)*TAN(PI()/$B$2) -> 2.8607047 | G13: =2*(G11+$B$1)*TAN(PI()/$B$2) -> 3.1195238 | H13: =2*(H11+$B$1)*TAN(PI()/$B$2) -> 3.3783428 | I13: =2*(I11+$B$1)*TAN(PI()/$B$2) -> 3.6371619 | ... AF13: =2*(AF11+$B$1)*TAN(PI()/$B$2) -> 9.5899999
A15: Stencil Variations
A16: Stencil Alpha
A17: Saw Cut Description: | B17: 90° Rip+2 Bevels | E17: Board Type: | G17: 0.75
A18: A1 Rip - Finish Side (in) | B18: =B13+$F$3 -> 1.8254285 | C18: =C13+$F$3 -> 2.0842476 | D18: =D13+$F$3 -> 2.3430666 | E18: =E13+$F$3 -> 2.6018857 | F18: =F13+$F$3 -> 2.8607047 | G18: =G13+$F$3 -> 3.1195238 | H18: =H13+$F$3 -> 3.3783428 | I18: =I13+$F$3 -> 3.6371619 | ... AF18: =AF13+$F$3 -> 9.5899999
A19: A1 Rip - Bottom Side (in)
A20: A2 Rip - Finish Side (in) | B20: =B18+B12+$F$3+$J$1 -> 3.3439333 | C20: =C18+C12+$F$3+$J$1 -> 3.8615714 | D20: =D18+D12+$F$3+$J$1 -> 4.3792095 | E20: =E18+E12+$F$3+$J$1 -> 4.8968476 | F20: =F18+F12+$F$3+$J$1 -> 5.4144856 | G20: =G18+G12+$F$3+$J$1 -> 5.9321237 | H20: =H18+H12+$F$3+$J$1 -> 6.4497618 | I20: =I18+I12+$F$3+$J$1 -> 6.9673999 | ... AF20: =AF18+AF12+$F$3+$J$1 -> 18.873076
A21: A2 Rip - Bottom Side (in)
A22: A3 Rip - Finish Side (in) | B22: =B18*2+2*$J$1+B12+$F$3 -> 5.2643618 | C22: =C18*2+2*$J$1+C12+$F$3 -> 6.040819 | D22: =D18*2+2*$J$1+D12+$F$3 -> 6.8172761 | E22: =E18*2+2*$J$1+E12+$F$3 -> 7.5937332 | F22: =F18*2+2*$J$1+F12+$F$3 -> 8.3701904 | G22: =G18*2+2*$J$1+G12+$F$3 -> 9.1466475 | H22: =H18*2+2*$J$1+H12+$F$3 -> 9.9231046 | I22: =I18*2+2*$J$1+I12+$F$3 -> 10.699562 | ... AF22: =AF18*2+2*$J$1+AF12+$F$3 -> 28.558076
A23: A3 Rip - Bottom Side (in)
A24: AX Rip (in)
A26: 3cuts/stave (90° Rip+2Bevel)
A29: 3cuts/stave (90° Rip+2Bevel)
A30: Volume of 3/4 Board Used (in^3) | B30: =ROUNDUP($B$1*B13*B8*$B$2,0) -> 161 | C30: =ROUNDUP($B$1*C13*C8*$B$2,0) -> 212 | D30: =ROUNDUP($B$1*D13*D8*$B$2,0) -> 269 | E30: =ROUNDUP($B$1*E13*E8*$B$2,0) -> 334 | F30: =ROUNDUP($B$1*F13*F8*$B$2,0) -> 406 | G30: =ROUNDUP($B$1*G13*G8*$B$2,0) -> 485 | H30: =ROUNDUP($B$1*H13*H8*$B$2,0) -> 571 | I30: =ROUNDUP($B$1*I13*I8*$B$2,0) -> 663 | ... AF30: =ROUNDUP($B$1*AF13*AF8*$B$2,0) -> 4726
A31: Cost of Wood | B31: =B30*($F$4+$J$4) -> 16.1 | C31: =C30*($F$4+$J$4) -> 21.2 | D31: =D30*($F$4+$J$4) -> 26.9 | E31: =E30*($F$4+$J$4) -> 33.4 | F31: =F30*($F$4+$J$4) -> 40.6 | G31: =G30*($F$4+$J$4) -> 48.5 | H31: =H30*($F$4+$J$4) -> 57.1 | I31: =I30*($F$4+$J$4) -> 66.3 | ... AF31: =AF30*($F$4+$J$4) -> 472.6
A32: 2cuts/stave Economy Bevel Rip (3:
A33: Volume of 3/4 Board Used (in^3) | B33: =ROUNDUP($B$1*B18*B11*$B$2,0) -> 44 | C33: =ROUNDUP($B$1*C18*C11*$B$2,0) -> 59 | D33: =ROUNDUP($B$1*D18*D11*$B$2,0) -> 77 | E33: =ROUNDUP($B$1*E18*E11*$B$2,0) -> 97 | F33: =ROUNDUP($B$1*F18*F11*$B$2,0) -> 119 | G33: =ROUNDUP($B$1*G18*G11*$B$2,0) -> 143 | H33: =ROUNDUP($B$1*H18*H11*$B$2,0) -> 169 | I33: =ROUNDUP($B$1*I18*I11*$B$2,0) -> 198 | ... AF33: =ROUNDUP($B$1*AF18*AF11*$B$2,0) -> 1480
A34: Cost of Wood | B34: =B33*($F$4+$J$4) -> 4.4 | C34: =C33*($F$4+$J$4) -> 5.9 | D34: =D33*($F$4+$J$4) -> 7.7 | E34: =E33*($F$4+$J$4) -> 9.7 | F34: =F33*($F$4+$J$4) -> 11.9 | G34: =G33*($F$4+$J$4) -> 14.3 | H34: =H33*($F$4+$J$4) -> 16.9 | I34: =I33*($F$4+$J$4) -> 19.8 | ... AF34: =AF33*($F$4+$J$4) -> 148
A40: Widths for Multiple Boards:
A41: Stencil Information
A42: Stenciled on Endgrain | B42: \ A1 / | C42: / A2 \ | D42: \ A3 / | I42: Glue Up:
A43: Stenciled on Face | I43: A1
A44: Wood Type 1 | C44: Wood Type 2 | I44: A1
A45: A1 | C45: A1 | I45: A2
A46: A2 - Finish Side Down | C46: A2 - Finish Side Down | I46: A2
A47: A3 | C47: A3 | I47: A3
A48: AX | I48: A3
A49: Note: A2 & B1:B3 are oriented with finish side down when looking at stenciled face of board.
A51: Number of Staves: | B51: 10 | C51: 12 | D51: 14 | E51: 16 | F51: 18 | G51: 20 | H51: 22 | I51: 24 | J51: 26 | K51: 28
...

Sheet Method
A1: Step | B1: Tool | C1: Set Up | D1: Stave | E1: Face
A2: Lengthwise Straight Edge Rip | B2: Radial Arm Saw | C2: Conserve AMAP
A3: Stencil | B3: Pencil & Tape Measure | D3: A & B | E3: none
A4: Rip: A1, A2, A3 | B4: Radial Arm Saw | C4: 30 degree bevel rip | D4: A | E4: Right & Left
A5: Rip: B1-B3 | B5: Radial Arm Saw | C5: 30 degree bevel rip | D5: B | E5: Right
A6: Xcut: Tops of A1-A3 | B6: Radial Arm Saw | C6: 90 degree Xcut | D6: A | E6: Top
A7: Xcut: Tops and Bottoms of B1-B3 | B7: Radial Arm Saw
A8: Dowel Bore into end grain: A1-A3 | B8: Drill Press | C8: 1/4" Bit
A9: Dowel Bore w/ 9.5 degree Jig: B1-B3 | B9: Drill Press | C9: 1/4" Bit
A10: 45 Miter: A1-A3 | B10: Radial Arm Saw
A11: Flute: A1-A3 | B11: Router
A12: 35.5 Miter: Tops of B1-B3 | B12: Radial Arm Saw
F17: Right
F18: Left
F19: Top
F20: Bottom
F21: Inside
F22: Outside
